# 参数与返回值

一个典型的函数定义如下，使用关键字 func，参数可以有多个，返回值也支持有多个。特别地，package main 中的func main() 约定为可执行程序的入口

```
func funcName(param1 Type1, param2 Type2, ...) (return1 Type3, ...) {
    // body
}
```

可以给返回值命名，简化 return

```
func add(num1 int, num2 int) (ans int) {
	ans = num1 + num2
	return
}
```

# 错误处理(error handling)

如果函数实现过程中，如果出现不能处理的错误，可以返回给调用者处理。比如我们调用标准库函数os.Open读取文件，os.Open 有2个返回值，第一个是 ```*File```，第二个是 ```error```， 如果调用成功，error 的值是 nil，如果调用失败，例如文件不存在，我们可以通过 error 知道具体的错误信息

```
import (
	"fmt"
	"os"
)

func main() {
	_, err := os.Open("filename.txt")
	if err != nil {
		fmt.Println(err)
	}
}

// open filename.txt: no such file or directory
```


可以通过 errorw.New 返回自定义的错误

```
import (
	"errors"
	"fmt"
)

func hello(name string) error {
	if len(name) == 0 {
		return errors.New("error: name is null")
	}
	fmt.Println("Hello,", name)
	return nil
}

func main() {
	if err := hello(""); err != nil {
		fmt.Println(err)
	}
}
// error: name is null
```


error 往往是能预知的错误，但是也可能出现一些不可预知的错误，例如数组越界，这种错误可能会导致程序非正常退出，在 Go 语言中称之为 panic

```
func get(index int) int {
	arr := [3]int{2, 3, 4}
	return arr[index]
}

func main() {
	fmt.Println(get(5))
	fmt.Println("finished")
}
```

结果：
```
$ go run .
panic: runtime error: index out of range [5] with length 3
goroutine 1 [running]:
exit status 2
```

在 Python、Java 等语言中有 try...catch 机制，在 try 中捕获各种类型的异常，在 catch 中定义异常处理的行为。Go 语言也提供了类似的机制 defer 和 recover

```
func get(index int) (ret int) {
	defer func() {
		if r := recover(); r != nil {
			fmt.Println("Some error happened!", r)
			ret = -1
		}
	}()
	arr := [3]int{2, 3, 4}
	return arr[index]
}

func main() {
	fmt.Println(get(5))
	fmt.Println("finished")
}
```

执行结果
```
$ go run .
Some error happened! runtime error: index out of range [5] with length 3
-1
finished
```


> 在 get 函数中，使用 defer 定义了异常处理的函数，在协程退出前，会执行完 defer 挂载的任务。因此如果触发了 panic，控制权就交给了 defer。
> 在 defer 的处理逻辑中，使用 recover，使程序恢复正常，并且将返回值设置为 -1，在这里也可以不处理返回值，如果不处理返回值，返回值将被置为默认值 0